Workbook

Sheet Index & Read Me
B2: WORKBOOK GUIDE · INDEX & READ ME
B3: Data Center Template, Northern Virginia — 90 MW Tier III hyperscale data center. Owner-side cost estimate + capital-program controls toolkit. Independent, illustrative model — not affiliated with any actual named project.
B5: TOTAL CAMPUS INVESTMENT | C5: IT CAPACITY · COST / MW · GROSS AREA · TABS
B6: ='Construction Budget'!H842 -> 1.0883418e+09 | C6: ='Campus Rollup'!D16&" MW · $"&TEXT('Construction Budget'!H843/1000000,"0.0")&"M / MW · "&TEXT('Campus Rollup'!C16,"#,##0")&" SF · 39 sheets" -> 90 MW · $12.1M / MW · 800,000 SF · 39 sheets
B8: EXECUTIVE & QA
B9: =HYPERLINK("#'Dashboard'!A1","Dashboard") -> Dashboard | C9: Executive summary — headline KPIs, five cost charts, six QC tie checks, and live delivery metrics (EVM / risk / procurement).
B10: =HYPERLINK("#'Basis of Estimate'!A1","Basis of Estimate") -> Basis of Estimate | C10: Methodology, inclusions / exclusions, key assumptions, and the scenario-control & value-engineering notes.
B11: COST ESTIMATE
B12: =HYPERLINK("#'Construction Budget'!A1","Construction Budget") -> Construction Budget | C12: The estimate spine — 25 CSI divisions, ~400 line items building to the $1.09B grand total.
B13: =HYPERLINK("#'Unit Cost Database'!A1","Unit Cost Database") -> Unit Cost Database | C13: Standard reference unit pricing; the active pricing tier (set on Scenario & Presets) drives the estimate.
B14: =HYPERLINK("#'Location Factors'!A1","Location Factors") -> Location Factors | C14: Regional cost-adjustment factors for the Loudoun County, VA market.
B15: =HYPERLINK("#'Allowances & Alternates'!A1","Allowances & Alternates") -> Allowances & Alternates | C15: Carried allowances and priced add/deduct alternates.
B16: =HYPERLINK("#'CSA Summary'!A1","CSA Summary") -> CSA Summary | C16: Civil / structural / architectural scope breakout.
B17: =HYPERLINK("#'Variance Tracker'!A1","Variance Tracker") -> Variance Tracker | C17: Estimate vs. subcontractor pricing by division.
B18: =HYPERLINK("#'Client Proposal'!A1","Client Proposal") -> Client Proposal | C18: Client-facing cost summary (Turner & Townsend format).
B19: CAMPUS & PROGRAM
B20: =HYPERLINK("#'Campus Rollup'!A1","Campus Rollup") -> Campus Rollup | C20: Per-building + shared-infrastructure rollup to the campus total; the hub every other tab references.
B21: =HYPERLINK("#'Phased Capital Plan'!A1","Phased Capital Plan") -> Phased Capital Plan | C21: Six-building sequential deployment; Phase 1 reconciles exactly to this estimate, then escalates to build-out.
B22: =HYPERLINK("#'Milestone Tracker'!A1","Milestone Tracker") -> Milestone Tracker | C22: Estimate evolution across design milestones (Concept → SD → DD → CD → GMP).
B23: DELIVERY CONTROLS
B24: =HYPERLINK("#'Cash Flow & EVM'!A1","Cash Flow & EVM") -> Cash Flow & EVM | C24: Earned-value S-curve with SPI / CPI, EAC / ETC, and PV reconciliation to budget at completion.
B25: =HYPERLINK("#'Draw Schedule'!A1","Draw Schedule") -> Draw Schedule | C25: 30-month construction draw / cash-flow schedule.
B26: =HYPERLINK("#'Risk & Contingency'!A1","Risk & Contingency") -> Risk & Contingency | C26: Risk register, analytical P50 / P80 / P90, and a 10,000-iteration Monte Carlo vs. the carried contingency.
B27: =HYPERLINK("#'Change Order Log'!A1","Change Order Log") -> Change Order Log | C27: Change orders with type / status / funding and a running contingency drawdown.
B28: =HYPERLINK("#'Procurement & Long-Lead'!A1","Procurement & Long-Lead") -> Procurement & Long-Lead | C28: Equipment lead times, back-calculated order-by dates, and escalation exposure with late-order flags.
B29: Construction Schedule | C29: Cradle-to-grave CPM master schedule — WBS, dependency-linked dates, critical path & month-by-month Gantt; NTP tied to Construction Budget start.
B30: Schedule Acceleration | C30: Scenario model to recover schedule toward the Q3-2028 target — acceleration levers with day-savings, cost premium & risk.
B31: DECISION SUPPORT
B32: =HYPERLINK("#'Scenario & Presets'!A1","Scenario & Presets") -> Scenario & Presets | C32: Control panel — pricing tier, cooling technology, resiliency tier, redundancy, and density presets that drive the whole model.
B33: =HYPERLINK("#'Scenario Comparison'!A1","Scenario Comparison") -> Scenario Comparison | C33: The live scenario beside three saved snapshots with $/MW deltas.
B34: =HYPERLINK("#'Value Engineering'!A1","Value Engineering") -> Value Engineering | C34: VE log with accept / reject decisions and a live VE-adjusted total.
B35: =HYPERLINK("#'Bid Leveling'!A1","Bid Leveling") -> Bid Leveling | C35: Price normalization across bidders for a single package.
B36: =HYPERLINK("#'Bid Evaluation'!A1","Bid Evaluation") -> Bid Evaluation | C36: Weighted CMAR / GMP scoring across six criteria with an auto recommendation.
B37: GC Bid Form | C37: Print-ready general-contractor bid form — 24 CSI divisions, alternates, unit prices, schedule, quals & signature; prices feed Bid Leveling.
B38: Bid Cover Sheet | C38: Sealed-bid cover sheet / envelope label with required-documents checklist; auto-fills from the GC Bid Form.
B39: =HYPERLINK("#'Power & Space Capacity'!A1","Power & Space Capacity") -> Power & Space Capacity | C39: IT-load-driven electrical / cooling / space sizing, binding-constraint, and stranded-capacity analysis.
B40: =HYPERLINK("#'Carbon & Sustainability'!A1","Carbon & Sustainability") -> Carbon & Sustainability | C40: Embodied + operational carbon vs. capex, with decarbonization levers.
B41: =HYPERLINK("#'TCO 8-Year'!A1","TCO 8-Year") -> TCO 8-Year | C41: Eight-year total-cost-of-ownership model.
B42: OWNER ECONOMICS
B43: =HYPERLINK("#'Total Development Cost'!A1","Total Development Cost") -> Total Development Cost | C43: All-in owner budget — construction plus land, utility, owner PM/soft costs, financing (IDC) and contingency.
...

Sheet Dashboard
B3: DATA CENTER CAMPUS
B4: =IFERROR(IF(OR('Campus Rollup'!B3="",'Campus Rollup'!B3=0),"Program Cost Estimate",'Campus Rollup'!B3&" — Cost Estimate"),"Program Cost Estimate") -> Data Center Template, Northern Virginia — Cost Estimate
B5: ="Prepared for "&IFERROR(IF(OR('Campus Rollup'!E3="",'Campus Rollup'!E3=0),"[Client]",'Campus Rollup'!E3),"[Client]")&" | "&IFERROR(IF(OR('Campus Rollup'!B4="",'Campus Rollup'!B4=0),"[Location]",'Campus Rollup'!B4),"[Location]")&" | "&'Campus Rollup'!H3&" Estimate ("&'Campus Rollup'!H4&") | "&TEXT('Campus Rollup'!E4,"mmmm d, yyyy") -> Prepared for Confidential Hyperscaler | Loudoun County, VA | Class 3 (DD) Estimate (−20% / +30%) | May 1, 2026
B8: TIER 1 · INVESTMENT & RETURNS
B11: DEVELOPMENT COST (ALL-IN) | E11: SPONSOR EQUITY | G11: LEVERED EQUITY IRR | I11: EQUITY MULTIPLE (LEV.)
B12: ='Capital Stack & Returns'!B7 -> 1.5128738e+09 | E12: ='Capital Stack & Returns'!B27 -> 6.0514951e+08 | G12: ='Capital Stack & Returns'!B46 -> 0.26651127 | I12: ='Capital Stack & Returns'!B47 -> 5.1974061
B14: UNLEVERED IRR | E14: STABILIZED YIELD-ON-COST | G14: STABILIZED DSCR | I14: DEVELOPMENT MARGIN
B15: ='Investment Pro Forma'!B33 -> 0.1744147 | E15: ='Investment Pro Forma'!B38 -> 0.10901442 | G15: ='Capital Stack & Returns'!B30 -> 2.37264 | I15: ='Investment Pro Forma'!B42 -> 0.67714491
B17: Levered to sponsor equity — figures link live to Capital Stack & Returns, Investment Pro Forma and Sources & Uses.
B18: TIER 2 · COST & BENCHMARKING
B20: TOTAL CAMPUS INVESTMENT | E20: IT CAPACITY | G20: COST PER MW | I20: GROSS BUILT AREA
B21: =IF('Campus Rollup'!H16=0,"$ —",IF('Campus Rollup'!H16>=1000000000,TEXT('Campus Rollup'!H16/1000000000,"$0.00")&"B",TEXT('Campus Rollup'!H16/1000000,"$0.0")&"M")) -> $1.09B | E21: =IF('Campus Rollup'!D16=0,"— MW",TEXT('Campus Rollup'!D16,"0.0")&" MW") -> 90.0 MW | G21: =IF(OR('Campus Rollup'!D16=0,'Campus Rollup'!H16=0),"$ —",TEXT('Campus Rollup'!H16/'Campus Rollup'!D16/1000000,"$0.0")&"M") -> $12.1M | I21: =IF('Campus Rollup'!C16=0,"— SF",IF('Campus Rollup'!C16>=1000000,TEXT('Campus Rollup'!C16/1000000,"0.00")&"M SF",TEXT('Campus Rollup'!C16/1000,"#,##0")&"K SF")) -> 800K SF
B23: =IF(COUNTIF('Campus Rollup'!D8:D13,">0")=0,"Awaiting building program","Across "&COUNTIF('Campus Rollup'!D8:D13,">0")&IF(COUNTIF('Campus Rollup'!D8:D13,">0")=1," building"," buildings")&" + shared infrastructure") -> Across 3 buildings + shared infrastructure | E23: ="Total IT load delivered" -> Total IT load delivered | G23: =IF(OR('Campus Rollup'!D16=0,'Campus Rollup'!H16=0),"vs "&TEXT('Benchmark Library'!L20/1000000,"$0.0")&"M benchmark",IF('Campus Rollup'!H16/'Campus Rollup'!D16<'Benchmark Library'!L20,"▼ Below industry median","▲ Above industry median")) -> ▲ Above industry median | I23: =IF('Campus Rollup'!C16=0,"$/SF — ",TEXT('Campus Rollup'!H16/'Campus Rollup'!C16,"$#,##0")&" / SF blended") -> $1,360 / SF blended
B24: ="Note: Development Cost (All-In) of "&TEXT('Total Development Cost'!C50/1000000,"$#,##0")&"M is the full owner budget (TDC) = Total Campus Investment / construction "&TEXT('Total Development Cost'!C46/1000000,"$#,##0")&"M + owner soft costs "&TEXT('Total Development Cost'!C47/1000000,"$#,##0")&"M + financing/IDC "&TEXT('Total Development Cost'!C48/1000000,"$#,##0")&"M + owner's contingency "&TEXT('Total Development Cost'!C49/1000000,"$#,##0")&"M. See Total Development Cost tab." -> Note: Development Cost (All-In) of $1,513M is the full owner budget (TDC) = Total Campus Investment / construction $1,088M + owner soft costs $269M + financing/IDC $84M + owner's contingency $72M. See Total Development Cost tab.
B25: DESIGN SCENARIOS — CAMPUS COST BY CONFIGURATION (90 MW / 800K SF) | H25: COST EVOLUTION BY DESIGN MILESTONE
B28: Design Scenario | C28: CSA | D28: MEP | E28: Cx / GC / Soft | F28: Total | G28: $ / MW
B29: ='Scenario Comparison'!B5&" — Base" -> Current (live) — Base | C29: ='Scenario Comparison'!B15 -> 2.7573192e+08 | D29: ='Scenario Comparison'!B16 -> 6.09161e+08 | E29: ='Scenario Comparison'!B17 -> 2.0344891e+08 | F29: ='Scenario Comparison'!B13 -> 1.0883418e+09 | G29: ='Scenario Comparison'!B14 -> 12092687
B30: ='Scenario Comparison'!C5 -> Reference — Hyperscale (Hybrid) | C30: ='Scenario Comparison'!C15 -> 4.1684051e+08 | D30: ='Scenario Comparison'!C16 -> 1080845097 | E30: ='Scenario Comparison'!C17 -> 2.605499e+08 | F30: ='Scenario Comparison'!C13 -> 1.7582355e+09 | G30: ='Scenario Comparison'!C14 -> 19535950
B31: ='Scenario Comparison'!D5 -> Air-Cooled (Chilled Water) | C31: ='Scenario Comparison'!D15 -> 4.1684051e+08 | D31: ='Scenario Comparison'!D16 -> 1002231672 | E31: ='Scenario Comparison'!D17 -> 2.5768586e+08 | F31: ='Scenario Comparison'!D13 -> 1.676758e+09 | G31: ='Scenario Comparison'!D14 -> 18630645
B32: ='Scenario Comparison'!E5 -> AI / HPC — Liquid Cooled | C32: ='Scenario Comparison'!E15 -> 6.1853019e+08 | D32: ='Scenario Comparison'!E16 -> 2069717493 | E32: ='Scenario Comparison'!E17 -> 3.3103934e+08 | F32: ='Scenario Comparison'!E13 -> 3.019287e+09 | G32: ='Scenario Comparison'!E14 -> 33547634
B33: Enterprise | C33: ='Scenario Comparison'!F15 -> 4.1684051e+08 | D33: ='Scenario Comparison'!F16 -> 1180628910 | E33: ='Scenario Comparison'!F17 -> 2.5768586e+08 | F33: ='Scenario Comparison'!F13 -> 1.8551553e+09 | G33: ='Scenario Comparison'!F14 -> 20612836
B34: Colocation | C34: ='Scenario Comparison'!G15 -> 4.1684051e+08 | D34: ='Scenario Comparison'!G16 -> 952120088 | E34: ='Scenario Comparison'!G17 -> 2.5768586e+08 | F34: ='Scenario Comparison'!G13 -> 1.6266465e+09 | G34: ='Scenario Comparison'!G14 -> 18073849
B35: Edge | C35: ='Scenario Comparison'!H15 -> 2.7573192e+08 | D35: ='Scenario Comparison'!H16 -> 578065774 | E35: ='Scenario Comparison'!H17 -> 2.0465606e+08 | F35: ='Scenario Comparison'!H13 -> 1.0584538e+09 | G35: ='Scenario Comparison'!H14 -> 11760597
B36: Typical (industry median) | C36: — | D36: — | E36: — | F36: ='Benchmark Library'!L20*'Campus Rollup'!D16 -> 1026000000 | G36: ='Benchmark Library'!L20 -> 11400000
B37: All design scenarios are modeled (linked to Scenario Comparison). Enterprise & Colocation share Air-Cooled's Mid · Chilled-Water cost — they differ only in tier / redundancy / density, which don't drive cost in this estimate. Typical = industry median $/MW × 90 MW.
B38: BENCHMARK POSITIONING | H38: INVESTMENT BY DISCIPLINE
B41: CURRENT ESTIMATE — $/MW
B42: =IF(OR('Campus Rollup'!D16=0,'Campus Rollup'!H16=0),"$ —",TEXT('Campus Rollup'!H16/'Campus Rollup'!D16/1000000,"$0.00")&"M") -> $12.09M | E42: INDUSTRY MEDIAN
E43: =TEXT('Benchmark Library'!L20/1000000,"$0.0")&"M / MW" -> $11.4M / MW
B44: =IF(OR('Campus Rollup'!D16=0,'Campus Rollup'!H16=0),"Populate buildings to compare against benchmark",IF('Campus Rollup'!H16/'Campus Rollup'!D16/1000000<'Benchmark Library'!L20/1000000,"▼ "&TEXT('Benchmark Library'!L20/1000000-'Campus Rollup'!H16/'Campus Rollup'!D16/1000000,"$0.0")&"M / MW below median ("&TEXT(('Campus Rollup'!H16/'Campus Rollup'!D16-'Benchmark Library'!L20)/'Benchmark Library'!L20,"+0.0%;-0.0%")&")","▲ "&TEXT('Campus Rollup'!H16/'Campus Rollup'!D16/1000000-'Benchmark Library'!L20/1000000,"$0.0")&"M / MW above median ("&TEXT(('Campus Rollup'!H16/'Campus Rollup'!D16-'Benchmark Library'!L20)/'Benchmark Library'!L20,"+0.0%;-0.0%")&")")) -> ▲ $0.7M / MW above median (+6.1%)
B45: ="Range across "&COUNTA('Benchmark Library'!B6:B15)&" comparable Tier III projects: "&TEXT('Benchmark Library'!L19/1000000,"$0.0")&"M – "&TEXT('Benchmark Library'!L22/1000000,"$0.0")&"M / MW" -> Range across 10 comparable Tier III projects: $9.8M – $17.8M / MW
B47: LOWEST COMPARABLE | D47: MEDIAN COMPARABLE | F47: HIGHEST COMPARABLE
B48: =TEXT('Benchmark Library'!L19/1000000,"$0.0")&"M / MW" -> $9.8M / MW | D48: =TEXT('Benchmark Library'!L20/1000000,"$0.0")&"M / MW" -> $11.4M / MW | F48: =TEXT('Benchmark Library'!L22/1000000,"$0.0")&"M / MW" -> $17.8M / MW
B50: TIER 3 · DELIVERY & CONTROLS
B52: KEY HIGHLIGHTS
B55: ◆ ESTIMATE CONFIDENCE | E55: ◆ VALUE ENGINEERING | H55: ◆ TENDER READINESS
B56: ='Campus Rollup'!H3 -> Class 3 (DD) | E56: =IF('Value Engineering'!H27=0,"In progress",TEXT('Value Engineering'!H27,"$#,##0")&" identified") -> $68,805,864 identified | H56: =IF(COUNTIF('Bid Leveling'!E14:E19,">0")=0,"Ready to bid",COUNTIF('Bid Leveling'!E14:E19,">0")&" bids received") -> Ready to bid
B58: ="Accuracy band "&'Campus Rollup'!H4&". Estimate built up from CSI-level detail across all 19 divisions, anchored against benchmark library of 10 comparable Tier III projects." -> Accuracy band −20% / +30%. Estimate built up from CSI-level detail across all 19 divisions, anchored against benchmark library of 10 comparable Tier III projects. | E58: =IF('Value Engineering'!L43=0,"Active scenario: "&'Value Engineering'!L41&" — no savings adopted yet; VE log open for client review.","Active scenario: "&'Value Engineering'!L41&" — "&TEXT('Value Engineering'!L43,"$#,##0")&" adopted ("&TEXT('Value Engineering'!L46,"0.0%")&" of base) → "&TEXT('Value Engineering'!L45,"$#,##0")&"/MW.") -> Active scenario: Balanced — $35,305,864 adopted (3.2% of base) → $11,700,400/MW. | H58: =IF(COUNTIF('Bid Leveling'!E14:E19,">0")=0,"Bid packages and tender documents prepared. Subcontractor outreach underway across structural, MEP, and specialty trades.","Bid leveling complete; recommendation under client review.") -> Bid packages and tender documents prepared. Subcontractor outreach underway across structural, MEP, and specialty trades.
B60: QC CHECKS
B61: Construction Budget total = Campus Rollup total | G61: =IF(ROUND('Construction Budget'!H842,0)=ROUND('Campus Rollup'!H16,0),"✅ Tie","❌ Off by "&TEXT('Construction Budget'!H842-'Campus Rollup'!H16,"$#,##0")) -> ✅ Tie | H61: ◆ SCOPE ADDS — ALLOWANCES & ALTERNATES
...

Sheet Scenario & Presets
A1: SCENARIO & PRESETS — PROJECT CONFIGURATION
A2: Pick an archetype preset for guidance, then set the active configuration. Pricing Tier and Cooling Technology drive the live estimate.
A4: 1 · PROJECT ARCHETYPE PRESET
A5: Select Archetype: | B5: Hyperscale
A6: Recommended configuration
A7: Resiliency Tier: | B7: =VLOOKUP($B$5,$A$32:$H$36,2,FALSE()) -> Tier III
A8: Redundancy: | B8: =VLOOKUP($B$5,$A$32:$H$36,3,FALSE()) -> N+1
A9: Rack Density: | B9: =VLOOKUP($B$5,$A$32:$H$36,4,FALSE()) -> High (15–30 kW)
A10: Cooling Technology: | B10: =VLOOKUP($B$5,$A$32:$H$36,5,FALSE()) -> Hybrid (As-Designed)
A11: Pricing Tier: | B11: =VLOOKUP($B$5,$A$32:$H$36,6,FALSE()) -> Mid
A12: Expected $/MW band: | B12: =TEXT(VLOOKUP($B$5,$A$32:$H$36,7,FALSE()),"$0.0")&"M – "&TEXT(VLOOKUP($B$5,$A$32:$H$36,8,FALSE()),"$0.0")&"M / MW" -> $9.5M – $14.0M / MW
A14: 2 · ACTIVE CONFIGURATION (drives the live model)
A15: Pricing Tier: | B15: Low | C15: → sets every unit cost (Unit Cost Database)
A16: Cooling Technology: | B16: Liquid-Cooled (DLC) | C16: → toggles Division 23 cooling scope (air / chilled-water / liquid)
A17: Resiliency Tier: | B17: Tier III | C17: → documentation & benchmark context
A18: Redundancy: | B18: N+1 | C18: → drives MEP via redundancy factor (critical power)
A19: Rack Density: | B19: High (15–30 kW) | C19: → drives MEP via rack-density factor
A21: 3 · LIVE SCENARIO IMPACT
A22: Estimate Total: | B22: ='Campus Rollup'!H16 -> 1.0883418e+09
A23: Cost per MW: | B23: =IF('Campus Rollup'!D16=0,"—",'Campus Rollup'!H16/'Campus Rollup'!D16) -> 12092687
A24: Selected-archetype band: | B24: =B12 -> $9.5M – $14.0M / MW
A25: Position vs archetype band: | B25: =IF('Campus Rollup'!D16=0,"—",IF('Campus Rollup'!H16/'Campus Rollup'!D16<VLOOKUP($B$5,$A$32:$H$36,7,FALSE())*1000000,"▼ Below archetype band",IF('Campus Rollup'!H16/'Campus Rollup'!D16>VLOOKUP($B$5,$A$32:$H$36,8,FALSE())*1000000,"▲ Above archetype band — review scope / density","● Within archetype band"))) -> ● Within archetype band
A29: REFERENCE TABLES — used by the dropdowns above. Do not edit.
A31: Archetype | B31: Tier | C31: Redundancy | D31: Rack Density | E31: Cooling Technology | F31: Pricing | G31: $/MW Low | H31: $/MW High
A32: Hyperscale | B32: Tier III | C32: N+1 | D32: High (15–30 kW) | E32: Hybrid (As-Designed) | F32: Mid | G32: 9.5 | H32: 14
A33: Enterprise | B33: Tier III+ | C33: 2N | D33: Medium (8–15 kW) | E33: Chilled Water (Air-Cooled) | F33: Mid | G33: 11 | H33: 16
A34: Colocation | B34: Tier III | C34: N+1 | D34: Medium (8–15 kW) | E34: Chilled Water (Air-Cooled) | F34: Mid | G34: 10 | H34: 15
A35: Edge | B35: Tier II | C35: N+1 | D35: Low (≤8 kW) | E35: Chilled Water (Air-Cooled) | F35: Low | G35: 8 | H35: 13
A36: AI / HPC | B36: Tier III+ | C36: 2N | D36: Ultra (30+ kW) | E36: Liquid-Cooled (DLC) | F36: High | G36: 14 | H36: 22
A38: COOLING TECHNOLOGY FACTORS (× Division 23 scope)
A39: Technology | B39: Air-side | C39: Chilled-water | D39: Liquid
A40: Hybrid (As-Designed) | B40: 1 | C40: 1 | D40: 1
A41: Chilled Water (Air-Cooled) | B41: 1 | C41: 1 | D41: 0
A42: Liquid-Cooled (DLC) | B42: 0.4 | C42: 0.6 | D42: 1
A43: Full Immersion | B43: 0.2 | C43: 0.5 | D43: 1.1
A45: Active cooling factors → | B45: =INDEX($B$40:$B$43,MATCH($B$16,$A$40:$A$43,0)) -> 0.4 | C45: =INDEX($C$40:$C$43,MATCH($B$16,$A$40:$A$43,0)) -> 0.6 | D45: =INDEX($D$40:$D$43,MATCH($B$16,$A$40:$A$43,0)) -> 1
A47: REDUNDANCY FACTORS (× critical-power train scope)
A48: Redundancy | B48: Factor
A49: N | B49: 0.85
A50: N+1 | B50: 1
...

Sheet Scenario Comparison
A1: SCENARIO COMPARISON
A2: Column B is the recommended/live case. Reference columns reflect each archetype incl. redundancy & rack-density drivers.
B4: ★ RECOMMENDED
A5: Configuration | B5: Current (live) | C5: Reference — Hyperscale (Hybrid) | D5: Air-Cooled (Chilled Water) | E5: AI / HPC — Liquid Cooled | F5: Enterprise | G5: Colocation | H5: Edge
A6: Pricing Tier | B6: ='Scenario & Presets'!B15 -> Low | C6: Mid | D6: Mid | E6: High | F6: Mid | G6: Mid | H6: Low
A7: Cooling Technology | B7: ='Scenario & Presets'!B16 -> Liquid-Cooled (DLC) | C7: Hybrid (As-Designed) | D7: Chilled Water (Air-Cooled) | E7: Liquid-Cooled (DLC) | F7: Chilled Water (Air-Cooled) | G7: Chilled Water (Air-Cooled) | H7: Chilled Water (Air-Cooled)
A8: Resiliency Tier | B8: ='Scenario & Presets'!B17 -> Tier III | C8: Tier III | D8: Tier III | E8: Tier III+ | F8: Tier III+ | G8: Tier III | H8: Tier II
A9: Redundancy | B9: ='Scenario & Presets'!B18 -> N+1 | C9: N+1 | D9: N+1 | E9: 2N | F9: 2N | G9: N+1 | H9: N+1
A10: Rack Density | B10: ='Scenario & Presets'!B19 -> High (15–30 kW) | C10: High (15–30 kW) | D10: High (15–30 kW) | E10: Ultra (30+ kW) | F10: Medium (8–15 kW) | G10: Medium (8–15 kW) | H10: Low (≤8 kW)
A12: COST OUTCOMES
A13: Total Estimate | B13: ='Campus Rollup'!H16 -> 1.0883418e+09 | C13: =C15+C16+C17 -> 1.7582355e+09 | D13: =D15+D16+D17 -> 1.676758e+09 | E13: =E15+E16+E17 -> 3.019287e+09 | F13: =F15+F16+F17 -> 1.8551553e+09 | G13: =G15+G16+G17 -> 1.6266465e+09 | H13: =H15+H16+H17 -> 1.0584538e+09
A14: Cost per MW | B14: ='Campus Rollup'!H16/'Campus Rollup'!D16 -> 12092687 | C14: =C13/'Campus Rollup'!$D$16 -> 19535950 | D14: =D13/'Campus Rollup'!$D$16 -> 18630645 | E14: =E13/'Campus Rollup'!$D$16 -> 33547634 | F14: =F13/'Campus Rollup'!$D$16 -> 20612836 | G14: =G13/'Campus Rollup'!$D$16 -> 18073849 | H14: =H13/'Campus Rollup'!$D$16 -> 11760597
A15: CSA (Shell & Structure) | B15: ='Campus Rollup'!E16 -> 2.7573192e+08 | C15: 4.1684051e+08 | D15: 4.1684051e+08 | E15: 6.1853019e+08 | F15: 4.1684051e+08 | G15: 4.1684051e+08 | H15: 2.7573192e+08
A16: MEP (Mechanical / Electrical) | B16: ='Campus Rollup'!F16 -> 6.09161e+08 | C16: 1080845097 | D16: 1002231672 | E16: 2069717493 | F16: 1180628910 | G16: 952120088 | H16: 578065774
A17: Other (Commissioning, GC, Soft) | B17: ='Campus Rollup'!G16 -> 2.0344891e+08 | C17: 2.605499e+08 | D17: 2.5768586e+08 | E17: 3.3103934e+08 | F17: 2.5768586e+08 | G17: 2.5768586e+08 | H17: 2.0465606e+08
A19: COST vs BASELINE (baseline = Reference — Hyperscale)
A20: Δ vs baseline ($) | B20: ='Campus Rollup'!H16-$C$13 -> -6.6989368e+08 | C20: =C13-$C$13 -> 0 | D20: =D13-$C$13 -> -81477469 | E20: =E13-$C$13 -> 1.2610515e+09 | F20: =F13-$C$13 -> 96919769 | G20: =G13-$C$13 -> -1.3158905e+08 | H20: =H13-$C$13 -> -6.9978175e+08
A21: Δ vs baseline (%) | B21: =('Campus Rollup'!H16-$C$13)/$C$13 -> -0.38100338 | C21: =(C13-$C$13)/$C$13 -> 0 | D21: =(D13-$C$13)/$C$13 -> -0.046340475 | E21: =(E13-$C$13)/$C$13 -> 0.7172256 | F21: =(F13-$C$13)/$C$13 -> 0.055123314 | G21: =(G13-$C$13)/$C$13 -> -0.07484154 | H21: =(H13-$C$13)/$C$13 -> -0.39800229
A22: $/MW vs median ($11.4M) | B22: ='Campus Rollup'!H16/'Campus Rollup'!D16-'Benchmark Library'!L20 -> 692686.97 | C22: =C14-'Benchmark Library'!L20 -> 8135950.1 | D22: =D14-'Benchmark Library'!L20 -> 7230644.8 | E22: =E14-'Benchmark Library'!L20 -> 22147634 | F22: =F14-'Benchmark Library'!L20 -> 9212836.4 | G22: =G14-'Benchmark Library'!L20 -> 6673849.5 | H22: =H14-'Benchmark Library'!L20 -> 360597.24
A24: VALUE-ENGINEERING OVERLAY (recommended case)
A25: Active VE Scenario | B25: ='Value Engineering'!L41 -> Balanced
A26: VE Savings (adopted) | B26: ='Value Engineering'!L43 -> 35305864
A27: VE-Adjusted Total | B27: ='Value Engineering'!L44 -> 1.053036e+09
A28: VE-Adjusted $/MW | B28: ='Value Engineering'!L45 -> 11700400
A29: Each archetype now reflects its redundancy (2N vs N+1) and rack-density premium on MEP.
A31: CARBON & SUSTAINABILITY
A32: Lifecycle Carbon (tCO₂e) | B32: ='Carbon & Sustainability'!B77 -> 683824 | C32: ='Carbon & Sustainability'!C77 -> 2552332
A33: Carbon Intensity (tCO₂e/SF) | B33: ='Carbon & Sustainability'!B78 -> 0.85478 | C33: ='Carbon & Sustainability'!C78 -> 3.190415
A34: Annual Operational (tCO₂e/yr) | B34: ='Carbon & Sustainability'!B76 -> 18921.6 | C34: ='Carbon & Sustainability'!C76 -> 143488.8
A35: Embodied Share (%) | B35: ='Carbon & Sustainability'!B79 -> 0.58494583 | C35: ='Carbon & Sustainability'!C79 -> 0.15671942
A36: Annual Water (ML/yr) | B36: ='Carbon & Sustainability'!B81 -> 126.144 | C36: ='Carbon & Sustainability'!C81 -> 1135.296
A37: WUE (L/kWh) | B37: ='Carbon & Sustainability'!B73 -> 0.2 | C37: ='Carbon & Sustainability'!C73 -> 1.8
A38: Carbon vs baseline (%) | B38: =(B32-C32)/C32 -> -0.73207874
A39: Carbon is driven by cooling strategy. Recommended Liquid-DLC design maps to the Efficient profile; Hyperscale-Hybrid baseline maps to Base. Air-cooled options (D–H) share modeled cost but differ in PUE/WUE — see the Carbon & Sustainability tab to compare Efficient / Base / Conservative scenarios in full.

Sheet Construction Budget
A1: DATA CENTER CONSTRUCTION BUDGET
A3: Project Name: | C3: Data Center Template, Northern Virginia | E3: Start Date: | F3: 46143
A4: Project Location: | C4: Loudoun County, VA | E4: Target Completion: | F4: Q1 2029
A5: Owner / Client: | C5: Confidential Hyperscaler | E5: Architect / Engineer: | F5: HKS / Page Southerland Page
A6: Total Facility Area (SF): | C6: ='Campus Rollup'!C16 -> 800000 | E6: Halls / Pods: | F6: 9 halls (3 per building × 3 bldgs)
A7: Tier Rating: | C7: Tier III | E7: Contingency %: | F7: 0.1 | G7: Escalation %: | H7: 0.035
A8: Design PUE: | C8: 1.4 | G8: Location Factor: | H8: ='Location Factors'!B6 -> 1
A9: Total IT Load (MW): | C9: ='Campus Rollup'!D16 -> 90 | G9: Estimate Date: | H9: =F3 -> 46143
A10: UPS Capacity (MW): | C10: =C9 -> 90
A11: Generator Capacity (MW): | C11: =C9*1.25 -> 112.5
A12: Cooling Capacity (tons): | C12: =C9*285 -> 25650
A13: Raised Floor Area (SF): | C13: =C6*0.55 -> 440000
A14: Redundancy: | C14: N+1
A16: # | B16: CSI Code | C16: Description | D16: Qty | E16: Unit | F16: Unit Cost ($) | G16: Contingency % | H16: Extended Cost ($) | I16: Building | J16: Scope
A18: SOFT COSTS / PRE-CONSTRUCTION | J18: Soft
A19: 1 | B19: SC 01 00 | C19: Architectural & Engineering Design Fees | D19: =$C$9 -> 90 | E19: MW | F19: 275000 | G19: =$F$7 -> 0.1 | H19: =IF(OR(D19="",F19="",D19=0,F19=0),0,D19*F19*$H$8*(1+G19)*(1+$H$7)) -> 28177875 | I19: Shared | J19: Soft
A20: 2 | B20: SC 02 00 | C20: MEP Engineering — Critical Systems Design | D20: =$C$9 -> 90 | E20: =IFERROR(VLOOKUP($B20,'Unit Cost Database'!$A:$H,3,FALSE()),"LS") -> MW | F20: =IFERROR(VLOOKUP($B20,'Unit Cost Database'!$A:$H,8,FALSE()),0) -> 225000 | G20: =$F$7 -> 0.1 | H20: =IF(OR(D20="",F20="",D20=0,F20=0),0,D20*F20*$H$8*(1+G20)*(1+$H$7)) -> 23054625 | I20: Shared | J20: Soft
A21: 3 | B21: SC 03 00 | C21: Structural Engineering | D21: =$C$9 -> 90 | E21: =IFERROR(VLOOKUP($B21,'Unit Cost Database'!$A:$H,3,FALSE()),"LS") -> MW | F21: =IFERROR(VLOOKUP($B21,'Unit Cost Database'!$A:$H,8,FALSE()),0) -> 65000 | G21: =$F$7 -> 0.1 | H21: =IF(OR(D21="",F21="",D21=0,F21=0),0,D21*F21*$H$8*(1+G21)*(1+$H$7)) -> 6660225 | I21: Shared | J21: Soft
A22: 4 | B22: SC 04 00 | C22: Civil Engineering & Survey | D22: =$C$9 -> 90 | E22: =IFERROR(VLOOKUP($B22,'Unit Cost Database'!$A:$H,3,FALSE()),"LS") -> MW | F22: =IFERROR(VLOOKUP($B22,'Unit Cost Database'!$A:$H,8,FALSE()),0) -> 35000 | G22: =$F$7 -> 0.1 | H22: =IF(OR(D22="",F22="",D22=0,F22=0),0,D22*F22*$H$8*(1+G22)*(1+$H$7)) -> 3586275 | I22: Shared | J22: Soft
A23: 5 | B23: SC 05 00 | C23: Geotechnical Investigation | D23: =3 -> 3 | E23: =IFERROR(VLOOKUP($B23,'Unit Cost Database'!$A:$H,3,FALSE()),"LS") -> EA | F23: =IFERROR(VLOOKUP($B23,'Unit Cost Database'!$A:$H,8,FALSE()),0) -> 125000 | G23: =$F$7 -> 0.1 | H23: =IF(OR(D23="",F23="",D23=0,F23=0),0,D23*F23*$H$8*(1+G23)*(1+$H$7)) -> 426937.5 | I23: Shared | J23: Soft
A24: 6 | B24: SC 06 00 | C24: Environmental Consulting / Phase I ESA | D24: =1 -> 1 | E24: =IFERROR(VLOOKUP($B24,'Unit Cost Database'!$A:$H,3,FALSE()),"LS") -> LS | F24: =IFERROR(VLOOKUP($B24,'Unit Cost Database'!$A:$H,8,FALSE()),0) -> 250000 | G24: =$F$7 -> 0.1 | H24: =IF(OR(D24="",F24="",D24=0,F24=0),0,D24*F24*$H$8*(1+G24)*(1+$H$7)) -> 284625 | I24: Shared | J24: Soft
A25: 7 | B25: SC 07 00 | C25: Permitting & Entitlement Fees | D25: =$C$9 -> 90 | E25: =IFERROR(VLOOKUP($B25,'Unit Cost Database'!$A:$H,3,FALSE()),"LS") -> MW | F25: =IFERROR(VLOOKUP($B25,'Unit Cost Database'!$A:$H,8,FALSE()),0) -> 85000 | G25: =$F$7 -> 0.1 | H25: =IF(OR(D25="",F25="",D25=0,F25=0),0,D25*F25*$H$8*(1+G25)*(1+$H$7)) -> 8709525 | I25: Shared | J25: Soft
A26: 8 | B26: SC 08 00 | C26: Utility Connection & Impact Fees | D26: =$C$9 -> 90 | E26: =IFERROR(VLOOKUP($B26,'Unit Cost Database'!$A:$H,3,FALSE()),"LS") -> MW | F26: =IFERROR(VLOOKUP($B26,'Unit Cost Database'!$A:$H,8,FALSE()),0) -> 175000 | G26: =$F$7 -> 0.1 | H26: =IF(OR(D26="",F26="",D26=0,F26=0),0,D26*F26*$H$8*(1+G26)*(1+$H$7)) -> 17931375 | I26: Shared | J26: Soft
A27: 9 | B27: SC 09 00 | C27: Third-Party Commissioning Agent (CxA) | D27: =$C$9 -> 90 | E27: =IFERROR(VLOOKUP($B27,'Unit Cost Database'!$A:$H,3,FALSE()),"LS") -> MW | F27: =IFERROR(VLOOKUP($B27,'Unit Cost Database'!$A:$H,8,FALSE()),0) -> 7500 | G27: =$F$7 -> 0.1 | H27: =IF(OR(D27="",F27="",D27=0,F27=0),0,D27*F27*$H$8*(1+G27)*(1+$H$7)) -> 768487.5 | I27: Shared | J27: Soft
A28: 10 | B28: SC 10 00 | C28: Uptime Institute Tier Certification | D28: =1 -> 1 | E28: LS | F28: 350000 | G28: =$F$7 -> 0.1 | H28: =IF(OR(D28="",F28="",D28=0,F28=0),0,D28*F28*$H$8*(1+G28)*(1+$H$7)) -> 398475 | I28: Shared | J28: Soft
A29: 11 | B29: SC 11 00 | C29: LEED / Sustainability Certification | D29: =1 -> 1 | E29: =IFERROR(VLOOKUP($B29,'Unit Cost Database'!$A:$H,3,FALSE()),"LS") -> LS | F29: =IFERROR(VLOOKUP($B29,'Unit Cost Database'!$A:$H,8,FALSE()),0) -> 250000 | G29: =$F$7 -> 0.1 | H29: =IF(OR(D29="",F29="",D29=0,F29=0),0,D29*F29*$H$8*(1+G29)*(1+$H$7)) -> 284625 | I29: Shared | J29: Soft
A30: 12 | B30: SC 12 00 | C30: Owner's Representative / PM Fees | D30: =24 -> 24 | E30: =IFERROR(VLOOKUP($B30,'Unit Cost Database'!$A:$H,3,FALSE()),"LS") -> MO | F30: =IFERROR(VLOOKUP($B30,'Unit Cost Database'!$A:$H,8,FALSE()),0) -> 95000 | G30: =$F$7 -> 0.1 | H30: =IF(OR(D30="",F30="",D30=0,F30=0),0,D30*F30*$H$8*(1+G30)*(1+$H$7)) -> 2595780 | I30: Shared | J30: Soft
A31: 13 | B31: SC 13 00 | C31: Legal & Contract Administration | D31: =24 -> 24 | E31: =IFERROR(VLOOKUP($B31,'Unit Cost Database'!$A:$H,3,FALSE()),"LS") -> MO | F31: =IFERROR(VLOOKUP($B31,'Unit Cost Database'!$A:$H,8,FALSE()),0) -> 25000 | G31: =$F$7 -> 0.1 | H31: =IF(OR(D31="",F31="",D31=0,F31=0),0,D31*F31*$H$8*(1+G31)*(1+$H$7)) -> 683100 | I31: Shared | J31: Soft
A32: 14 | B32: SC 14 00 | C32: Cost Estimating / QS Services | D32: =24 -> 24 | E32: =IFERROR(VLOOKUP($B32,'Unit Cost Database'!$A:$H,3,FALSE()),"LS") -> MO | F32: =IFERROR(VLOOKUP($B32,'Unit Cost Database'!$A:$H,8,FALSE()),0) -> 35000 | G32: =$F$7 -> 0.1 | H32: =IF(OR(D32="",F32="",D32=0,F32=0),0,D32*F32*$H$8*(1+G32)*(1+$H$7)) -> 956340 | I32: Shared | J32: Soft
A33: 15 | B33: SC 15 00 | C33: Building Information Modeling (BIM) | D33: =$C$9 -> 90 | E33: MW | F33: 85000 | G33: =$F$7 -> 0.1 | H33: =IF(OR(D33="",F33="",D33=0,F33=0),0,D33*F33*$H$8*(1+G33)*(1+$H$7)) -> 8709525 | I33: Shared | J33: Soft
A34: 16 | B34: SC 16 00 | C34: Third-Party Testing & Inspection (IOR) | D34: =24 -> 24 | E34: =IFERROR(VLOOKUP($B34,'Unit Cost Database'!$A:$H,3,FALSE()),"LS") -> MO | F34: =IFERROR(VLOOKUP($B34,'Unit Cost Database'!$A:$H,8,FALSE()),0) -> 55000 | G34: =$F$7 -> 0.1 | H34: =IF(OR(D34="",F34="",D34=0,F34=0),0,D34*F34*$H$8*(1+G34)*(1+$H$7)) -> 1502820 | I34: Shared | J34: Soft
A35: 17 | B35: SC 17 00 | C35: FF&E — NOC / SOC / Office Fit-Out | D35: =$C$6*0.05 -> 40000 | E35: =IFERROR(VLOOKUP($B35,'Unit Cost Database'!$A:$H,3,FALSE()),"LS") -> SF | F35: =IFERROR(VLOOKUP($B35,'Unit Cost Database'!$A:$H,8,FALSE()),0) -> 175 | G35: =$F$7 -> 0.1 | H35: =IF(OR(D35="",F35="",D35=0,F35=0),0,D35*F35*$H$8*(1+G35)*(1+$H$7)) -> 7969500 | I35: Shared | J35: Soft
A36: 18 | B36: SC 18 00 | C36: Move Management & Logistics | D36: =1 -> 1 | E36: =IFERROR(VLOOKUP($B36,'Unit Cost Database'!$A:$H,3,FALSE()),"LS") -> LS | F36: =IFERROR(VLOOKUP($B36,'Unit Cost Database'!$A:$H,8,FALSE()),0) -> 350000 | G36: =$F$7 -> 0.1 | H36: =IF(OR(D36="",F36="",D36=0,F36=0),0,D36*F36*$H$8*(1+G36)*(1+$H$7)) -> 398475 | I36: Shared | J36: Soft
C37: Subtotal — SOFT COSTS / PRE-CONSTRUCTION | H37: =SUM(H19:H36) -> 113098590
A39: GENERAL CONDITIONS & REQUIREMENTS | J39: GC
A40: 1 | B40: 01 10 00 | C40: Project Management & Supervision | D40: =24 -> 24 | E40: =IFERROR(VLOOKUP($B40,'Unit Cost Database'!$A:$H,3,FALSE()),"LS") -> MO | F40: =IFERROR(VLOOKUP($B40,'Unit Cost Database'!$A:$H,8,FALSE()),0) -> 80000 | G40: =$F$7 -> 0.1 | H40: =IF(OR(D40="",F40="",D40=0,F40=0),0,D40*F40*$H$8*(1+G40)*(1+$H$7)) -> 2185920 | I40: Shared | J40: GC
A41: 2 | B41: 01 20 00 | C41: Price & Payment Procedures | D41: =24 -> 24 | E41: =IFERROR(VLOOKUP($B41,'Unit Cost Database'!$A:$H,3,FALSE()),"LS") -> MO | F41: =IFERROR(VLOOKUP($B41,'Unit Cost Database'!$A:$H,8,FALSE()),0) -> 17500 | G41: =$F$7 -> 0.1 | H41: =IF(OR(D41="",F41="",D41=0,F41=0),0,D41*F41*$H$8*(1+G41)*(1+$H$7)) -> 478170 | I41: Shared | J41: GC
A42: 3 | B42: 01 30 00 | C42: Administrative Requirements | D42: =24 -> 24 | E42: =IFERROR(VLOOKUP($B42,'Unit Cost Database'!$A:$H,3,FALSE()),"LS") -> MO | F42: =IFERROR(VLOOKUP($B42,'Unit Cost Database'!$A:$H,8,FALSE()),0) -> 12600 | G42: =$F$7 -> 0.1 | H42: =IF(OR(D42="",F42="",D42=0,F42=0),0,D42*F42*$H$8*(1+G42)*(1+$H$7)) -> 344282.4 | I42: Shared | J42: GC
A43: 4 | B43: 01 31 00 | C43: Project Management Software (Procore/Primavera) | D43: =24 -> 24 | E43: =IFERROR(VLOOKUP($B43,'Unit Cost Database'!$A:$H,3,FALSE()),"LS") -> MO | F43: =IFERROR(VLOOKUP($B43,'Unit Cost Database'!$A:$H,8,FALSE()),0) -> 5950 | G43: =$F$7 -> 0.1 | H43: =IF(OR(D43="",F43="",D43=0,F43=0),0,D43*F43*$H$8*(1+G43)*(1+$H$7)) -> 162577.8 | I43: Shared | J43: GC
A44: 5 | B44: 01 40 00 | C44: Quality Requirements — QA/QC Program | D44: =24 -> 24 | E44: =IFERROR(VLOOKUP($B44,'Unit Cost Database'!$A:$H,3,FALSE()),"LS") -> MO | F44: =IFERROR(VLOOKUP($B44,'Unit Cost Database'!$A:$H,8,FALSE()),0) -> 45500 | G44: =$F$7 -> 0.1 | H44: =IF(OR(D44="",F44="",D44=0,F44=0),0,D44*F44*$H$8*(1+G44)*(1+$H$7)) -> 1243242 | I44: Shared | J44: GC
...

Sheet Campus Rollup
A1: DATA CENTER CAMPUS — PROGRAM-LEVEL ROLLUP
A3: Program Name: | B3: Data Center Template, Northern Virginia | D3: Client: | E3: Confidential Hyperscaler | G3: Estimate Class: | H3: Class 3 (DD)
A4: Location: | B4: Loudoun County, VA | D4: Estimate Date: | E4: ='Construction Budget'!F3 -> 46143 | G4: Accuracy Range: | H4: =IFERROR(CHOOSE(MATCH(H3,{"Class 5 (Concept)","Class 4 (SD)","Class 3 (DD)","Class 2 (CD)","Class 1 (GMP/Tender)"},0),"−50% / +100%","−30% / +50%","−20% / +30%","−10% / +20%","−5% / +10%"),"") -> −20% / +30%
A6: BUILDING-BY-BUILDING SUMMARY
A7: # | B7: Building | C7: GBA (SF) | D7: IT Load (MW) | E7: CSA Cost | F7: MEP Cost | G7: Other (Cx/GC/Soft) | H7: Total | I7: $/SF | J7: $/MW
A8: 1 | B8: Building 1 (B1) | C8: 250000 | D8: 30 | E8: =SUMIFS('Construction Budget'!H:H,'Construction Budget'!I:I,"All Buildings",'Construction Budget'!J:J,"CSA")/3 -> 59235638 | F8: =SUMIFS('Construction Budget'!H:H,'Construction Budget'!I:I,"All Buildings",'Construction Budget'!J:J,"MEP")/3*'Scenario & Presets'!$B$67 -> 2.0305367e+08 | G8: =(SUMIFS('Construction Budget'!H:H,'Construction Budget'!I:I,"All Buildings",'Construction Budget'!J:J,"Cx")+SUMIFS('Construction Budget'!H:H,'Construction Budget'!I:I,"All Buildings",'Construction Budget'!J:J,"GC")+SUMIFS('Construction Budget'!H:H,'Construction Budget'!I:I,"All Buildings",'Construction Budget'!J:J,"Soft"))/3 -> 15789098 | H8: =E8+F8+G8 -> 2.780784e+08 | I8: =IF(C8=0,"—",H8/C8) -> 1112.3136 | J8: =IF(D8=0,"—",H8/D8) -> 9269280.1
A9: 2 | B9: Building 2 (B2) | C9: 250000 | D9: 30 | E9: =SUMIFS('Construction Budget'!H:H,'Construction Budget'!I:I,"All Buildings",'Construction Budget'!J:J,"CSA")/3 -> 59235638 | F9: =SUMIFS('Construction Budget'!H:H,'Construction Budget'!I:I,"All Buildings",'Construction Budget'!J:J,"MEP")/3*'Scenario & Presets'!$B$67 -> 2.0305367e+08 | G9: =(SUMIFS('Construction Budget'!H:H,'Construction Budget'!I:I,"All Buildings",'Construction Budget'!J:J,"Cx")+SUMIFS('Construction Budget'!H:H,'Construction Budget'!I:I,"All Buildings",'Construction Budget'!J:J,"GC")+SUMIFS('Construction Budget'!H:H,'Construction Budget'!I:I,"All Buildings",'Construction Budget'!J:J,"Soft"))/3 -> 15789098 | H9: =E9+F9+G9 -> 2.780784e+08 | I9: =IF(C9=0,"—",H9/C9) -> 1112.3136 | J9: =IF(D9=0,"—",H9/D9) -> 9269280.1
A10: 3 | B10: Building 3 (B3) | C10: 250000 | D10: 30 | E10: =SUMIFS('Construction Budget'!H:H,'Construction Budget'!I:I,"All Buildings",'Construction Budget'!J:J,"CSA")/3 -> 59235638 | F10: =SUMIFS('Construction Budget'!H:H,'Construction Budget'!I:I,"All Buildings",'Construction Budget'!J:J,"MEP")/3*'Scenario & Presets'!$B$67 -> 2.0305367e+08 | G10: =(SUMIFS('Construction Budget'!H:H,'Construction Budget'!I:I,"All Buildings",'Construction Budget'!J:J,"Cx")+SUMIFS('Construction Budget'!H:H,'Construction Budget'!I:I,"All Buildings",'Construction Budget'!J:J,"GC")+SUMIFS('Construction Budget'!H:H,'Construction Budget'!I:I,"All Buildings",'Construction Budget'!J:J,"Soft"))/3 -> 15789098 | H10: =E10+F10+G10 -> 2.780784e+08 | I10: =IF(C10=0,"—",H10/C10) -> 1112.3136 | J10: =IF(D10=0,"—",H10/D10) -> 9269280.1
A11: 4 | B11: Building 4 (B4) | C11: 0 | D11: 0 | E11: 0 | F11: 0 | G11: 0 | H11: =E11+F11+G11 -> 0 | I11: =IF(C11=0,"—",H11/C11) -> — | J11: =IF(D11=0,"—",H11/D11) -> —
A12: 5 | B12: Building 5 (B5) | C12: 0 | D12: 0 | E12: 0 | F12: 0 | G12: 0 | H12: =E12+F12+G12 -> 0 | I12: =IF(C12=0,"—",H12/C12) -> — | J12: =IF(D12=0,"—",H12/D12) -> —
A13: 6 | B13: Building 6 (B6) | C13: 0 | D13: 0 | E13: 0 | F13: 0 | G13: 0 | H13: =E13+F13+G13 -> 0 | I13: =IF(C13=0,"—",H13/C13) -> — | J13: =IF(D13=0,"—",H13/D13) -> —
A14: S | B14: Shared Infrastructure | C14: 50000 | D14: 0 | E14: =SUMIFS('Construction Budget'!H:H,'Construction Budget'!I:I,"Shared",'Construction Budget'!J:J,"CSA") -> 98025002 | F14: =SUMIFS('Construction Budget'!H:H,'Construction Budget'!I:I,"Shared",'Construction Budget'!J:J,"MEP")*'Scenario & Presets'!$B$67 -> 0 | G14: =SUMIFS('Construction Budget'!H:H,'Construction Budget'!I:I,"Shared",'Construction Budget'!J:J,"Cx")+SUMIFS('Construction Budget'!H:H,'Construction Budget'!I:I,"Shared",'Construction Budget'!J:J,"GC")+SUMIFS('Construction Budget'!H:H,'Construction Budget'!I:I,"Shared",'Construction Budget'!J:J,"Soft") -> 1.5608162e+08 | H14: =E14+F14+G14 -> 2.5410662e+08 | I14: — | J14: —
B16: CAMPUS TOTAL | C16: =SUM(C8:C14) -> 800000 | D16: =SUM(D8:D14) -> 90 | E16: =SUM(E8:E14) -> 2.7573192e+08 | F16: =SUM(F8:F14) -> 6.09161e+08 | G16: =SUM(G8:G14) -> 2.0344891e+08 | H16: =SUM(H8:H14) -> 1.0883418e+09 | I16: =IF(C16=0,"—",H16/C16) -> 1360.4273 | J16: =IF(D16=0,"—",H16/D16) -> 12092687
A18: PROGRAM-LEVEL METRICS
A20: CSA Share of Total: | B20: =IF(H16=0,0,E16/H16) -> 0.25335047 | D20: MEP Share of Total: | E20: =IF(H16=0,0,F16/H16) -> 0.55971477 | G20: Other Share: | H20: =IF(H16=0,0,G16/H16) -> 0.18693476
A21: Campus $/SF (excl. Shared): | B21: =IF(SUM(C8:C13)=0,"—",SUM(H8:H13)/SUM(C8:C13)) -> 1112.3136 | D21: Campus $/MW (incl. Shared): | E21: =IF(D16=0,"—",H16/D16) -> 12092687 | G21: Cost per Watt: | H21: =IF(D16=0,"—",H16/(D16*1000000)) -> 12.092687
A23: PROGRAM ECONOMICS — ALL-IN (bridge to TDC)
A24: Hard construction (this tab): | B24: =H16 -> 1.0883418e+09 | D24: All-in development cost: | E24: ='Total Development Cost'!C35 -> 1.5128738e+09 | G24: Hard cost % of all-in: | H24: =H16/'Total Development Cost'!C35 -> 0.71938706
A25: Construction $/MW: | B25: =H16/D16 -> 12092687 | D25: All-in $/MW: | E25: ='Total Development Cost'!C35/D16 -> 16809709 | G25: Capex uplift $/MW: | H25: =('Total Development Cost'!C35-H16)/D16 -> 4717021.7
A26: Construction $/SF (incl. shared): | B26: =H16/C16 -> 1360.4273 | D26: All-in $/SF: | E26: ='Total Development Cost'!C35/C16 -> 1891.0922 | G26: All-in cost per Watt: | H26: ='Total Development Cost'!C35/(D16*1000000) -> 16.809709
A27: Senior loan (60% LTC): | B27: ='Capital Stack & Returns'!B25 -> 9.0772427e+08 | D27: Sponsor equity: | E27: ='Capital Stack & Returns'!B27 -> 6.0514951e+08 | G27: Loan-to-cost: | H27: ='Capital Stack & Returns'!B29 -> 0.6
A29: NOTES
A30: • Tag each Construction Budget line in column I (Building) to one of B1–B6 or "Shared" so it rolls up here.
A31: • Column J (Scope) auto-classifies CSA / MEP / Cx / GC / Soft based on division. Override per line if needed.
A32: • Shared Infrastructure = site-wide utilities, security perimeter, central plant, common roads — not allocated to a specific building.
A33: • Campus $/SF excludes Shared Infra (which has no allocable SF). Campus $/MW includes Shared (allocated against total IT load).
A36: — chart source data —
A37: CSA (core & shell) | B37: =E16 -> 2.7573192e+08
A38: MEP (power & cooling) | B38: =F16 -> 6.09161e+08
A39: Other (Cx / GC / soft) | B39: =G16 -> 2.0344891e+08

Sheet CSA Summary
A1: CIVIL / STRUCTURAL / ARCHITECTURAL (CSA) ESTIMATE SUMMARY
A3: Scope: | B3: Civil + Structural + Architectural (excludes MEP, Cx, GC, Soft Costs)
A5: CSA DIVISION | B5: Base (current) | C5: Hyperscale (Hybrid) | D5: Air-Cooled | E5: AI / HPC (Liquid)
A6: Earthwork (Div 31) | B6: =SUMIFS('Construction Budget'!$H$744:$H$771,'Construction Budget'!$I$744:$I$771,"All Buildings")+SUMIFS('Construction Budget'!$H$744:$H$771,'Construction Budget'!$I$744:$I$771,"Shared") -> 25614732 | C6: =$B6*('Scenario Comparison'!C$15/'Scenario Comparison'!$B$15) -> 38723330 | D6: =$B6*('Scenario Comparison'!D$15/'Scenario Comparison'!$B$15) -> 38723330 | E6: =$B6*('Scenario Comparison'!E$15/'Scenario Comparison'!$B$15) -> 57459743
A7: Exterior Improvements (Div 32) | B7: =SUMIFS('Construction Budget'!$H$775:$H$791,'Construction Budget'!$I$775:$I$791,"All Buildings")+SUMIFS('Construction Budget'!$H$775:$H$791,'Construction Budget'!$I$775:$I$791,"Shared") -> 9371809.5 | C7: =$B7*('Scenario Comparison'!C$15/'Scenario Comparison'!$B$15) -> 14167928 | D7: =$B7*('Scenario Comparison'!D$15/'Scenario Comparison'!$B$15) -> 14167928 | E7: =$B7*('Scenario Comparison'!E$15/'Scenario Comparison'!$B$15) -> 21023127
A8: Utilities (Div 33) | B8: =SUMIFS('Construction Budget'!$H$795:$H$834,'Construction Budget'!$I$795:$I$834,"All Buildings")+SUMIFS('Construction Budget'!$H$795:$H$834,'Construction Budget'!$I$795:$I$834,"Shared") -> 63598602 | C8: =$B8*('Scenario Comparison'!C$15/'Scenario Comparison'!$B$15) -> 96145829 | D8: =$B8*('Scenario Comparison'!D$15/'Scenario Comparison'!$B$15) -> 96145829 | E8: =$B8*('Scenario Comparison'!E$15/'Scenario Comparison'!$B$15) -> 1.4266631e+08
A9: Concrete (Div 03) | B9: =SUMIFS('Construction Budget'!$H$78:$H$111,'Construction Budget'!$I$78:$I$111,"All Buildings")+SUMIFS('Construction Budget'!$H$78:$H$111,'Construction Budget'!$I$78:$I$111,"Shared") -> 33466040 | C9: =$B9*('Scenario Comparison'!C$15/'Scenario Comparison'!$B$15) -> 50592624 | D9: =$B9*('Scenario Comparison'!D$15/'Scenario Comparison'!$B$15) -> 50592624 | E9: =$B9*('Scenario Comparison'!E$15/'Scenario Comparison'!$B$15) -> 75072036
A10: Metals / Structural Steel (Div 05) | B10: =SUMIFS('Construction Budget'!$H$129:$H$163,'Construction Budget'!$I$129:$I$163,"All Buildings")+SUMIFS('Construction Budget'!$H$129:$H$163,'Construction Budget'!$I$129:$I$163,"Shared") -> 40836400 | C10: =$B10*('Scenario Comparison'!C$15/'Scenario Comparison'!$B$15) -> 61734840 | D10: =$B10*('Scenario Comparison'!D$15/'Scenario Comparison'!$B$15) -> 61734840 | E10: =$B10*('Scenario Comparison'!E$15/'Scenario Comparison'!$B$15) -> 91605450
A11: Thermal & Moisture (Div 07) | B11: =SUMIFS('Construction Budget'!$H$177:$H$211,'Construction Budget'!$I$177:$I$211,"All Buildings")+SUMIFS('Construction Budget'!$H$177:$H$211,'Construction Budget'!$I$177:$I$211,"Shared") -> 38165651 | C11: =$B11*('Scenario Comparison'!C$15/'Scenario Comparison'!$B$15) -> 57697308 | D11: =$B11*('Scenario Comparison'!D$15/'Scenario Comparison'!$B$15) -> 57697308 | E11: =$B11*('Scenario Comparison'!E$15/'Scenario Comparison'!$B$15) -> 85614345
A12: Openings (Div 08) | B12: =SUMIFS('Construction Budget'!$H$215:$H$238,'Construction Budget'!$I$215:$I$238,"All Buildings")+SUMIFS('Construction Budget'!$H$215:$H$238,'Construction Budget'!$I$215:$I$238,"Shared") -> 13742210 | C12: =$B12*('Scenario Comparison'!C$15/'Scenario Comparison'!$B$15) -> 20774925 | D12: =$B12*('Scenario Comparison'!D$15/'Scenario Comparison'!$B$15) -> 20774925 | E12: =$B12*('Scenario Comparison'!E$15/'Scenario Comparison'!$B$15) -> 30826942
A13: Finishes (Div 09) | B13: =SUMIFS('Construction Budget'!$H$242:$H$271,'Construction Budget'!$I$242:$I$271,"All Buildings")+SUMIFS('Construction Budget'!$H$242:$H$271,'Construction Budget'!$I$242:$I$271,"Shared") -> 33189552 | C13: =$B13*('Scenario Comparison'!C$15/'Scenario Comparison'!$B$15) -> 50174640 | D13: =$B13*('Scenario Comparison'!D$15/'Scenario Comparison'!$B$15) -> 50174640 | E13: =$B13*('Scenario Comparison'!E$15/'Scenario Comparison'!$B$15) -> 74451809
A14: Specialties (Div 10) | B14: =SUMIFS('Construction Budget'!$H$275:$H$291,'Construction Budget'!$I$275:$I$291,"All Buildings")+SUMIFS('Construction Budget'!$H$275:$H$291,'Construction Budget'!$I$275:$I$291,"Shared") -> 4010233.4 | C14: =$B14*('Scenario Comparison'!C$15/'Scenario Comparison'!$B$15) -> 6062510.9 | D14: =$B14*('Scenario Comparison'!D$15/'Scenario Comparison'!$B$15) -> 6062510.9 | E14: =$B14*('Scenario Comparison'!E$15/'Scenario Comparison'!$B$15) -> 8995877.2
A15: Masonry (Div 04) | B15: =SUMIFS('Construction Budget'!$H$115:$H$125,'Construction Budget'!$I$115:$I$125,"All Buildings")+SUMIFS('Construction Budget'!$H$115:$H$125,'Construction Budget'!$I$115:$I$125,"Shared") -> 5656068 | C15: =$B15*('Scenario Comparison'!C$15/'Scenario Comparison'!$B$15) -> 8550617.9 | D15: =$B15*('Scenario Comparison'!D$15/'Scenario Comparison'!$B$15) -> 8550617.9 | E15: =$B15*('Scenario Comparison'!E$15/'Scenario Comparison'!$B$15) -> 12687863
A16: Wood, Plastics & Composites (Div 06) | B16: =SUMIFS('Construction Budget'!$H$167:$H$173,'Construction Budget'!$I$167:$I$173,"All Buildings")+SUMIFS('Construction Budget'!$H$167:$H$173,'Construction Budget'!$I$167:$I$173,"Shared") -> 1233678.6 | C16: =$B16*('Scenario Comparison'!C$15/'Scenario Comparison'!$B$15) -> 1865026.1 | D16: =$B16*('Scenario Comparison'!D$15/'Scenario Comparison'!$B$15) -> 1865026.1 | E16: =$B16*('Scenario Comparison'!E$15/'Scenario Comparison'!$B$15) -> 2767425.2
A17: Equipment (Div 11) | B17: =SUMIFS('Construction Budget'!$H$295:$H$304,'Construction Budget'!$I$295:$I$304,"All Buildings")+SUMIFS('Construction Budget'!$H$295:$H$304,'Construction Budget'!$I$295:$I$304,"Shared") -> 1525590 | C17: =$B17*('Scenario Comparison'!C$15/'Scenario Comparison'!$B$15) -> 2306326.1 | D17: =$B17*('Scenario Comparison'!D$15/'Scenario Comparison'!$B$15) -> 2306326.1 | E17: =$B17*('Scenario Comparison'!E$15/'Scenario Comparison'!$B$15) -> 3422249.7
A18: Furnishings (Div 12) | B18: =SUMIFS('Construction Budget'!$H$308:$H$314,'Construction Budget'!$I$308:$I$314,"All Buildings")+SUMIFS('Construction Budget'!$H$308:$H$314,'Construction Budget'!$I$308:$I$314,"Shared") -> 1217056.5 | C18: =$B18*('Scenario Comparison'!C$15/'Scenario Comparison'!$B$15) -> 1839897.5 | D18: =$B18*('Scenario Comparison'!D$15/'Scenario Comparison'!$B$15) -> 1839897.5 | E18: =$B18*('Scenario Comparison'!E$15/'Scenario Comparison'!$B$15) -> 2730138
A19: Conveying Equipment (Div 14) | B19: =SUMIFS('Construction Budget'!$H$318:$H$323,'Construction Budget'!$I$318:$I$323,"All Buildings")+SUMIFS('Construction Budget'!$H$318:$H$323,'Construction Budget'!$I$318:$I$323,"Shared") -> 4104292.5 | C19: =$B19*('Scenario Comparison'!C$15/'Scenario Comparison'!$B$15) -> 6204705.6 | D19: =$B19*('Scenario Comparison'!D$15/'Scenario Comparison'!$B$15) -> 6204705.6 | E19: =$B19*('Scenario Comparison'!E$15/'Scenario Comparison'!$B$15) -> 9206873.4
A21: TOTAL CSA | B21: =SUM(B6:B19) -> 2.7573192e+08 | C21: =SUM(C6:C19) -> 4.1684051e+08 | D21: =SUM(D6:D19) -> 4.1684051e+08 | E21: =SUM(E6:E19) -> 6.1853019e+08
A22: Hyperscale / Air-Cooled / AI-HPC = Base division mix scaled to each scenario's CSA total (Scenario Comparison) — indicative, not separately estimated.
A23: CSA UNIT METRICS
A24: GBA (SF) | B24: ='Campus Rollup'!$C$16 -> 800000 | C24: ='Campus Rollup'!$C$16 -> 800000 | D24: ='Campus Rollup'!$C$16 -> 800000 | E24: ='Campus Rollup'!$C$16 -> 800000
A25: CSA $/SF | B25: =B21/B24 -> 344.66489 | C25: =C21/C24 -> 521.05064 | D25: =D21/D24 -> 521.05064 | E25: =E21/E24 -> 773.16274
A27: CSA IN CONTEXT
A28: Total CSA cost | B28: =B21 -> 2.7573192e+08
A29: Campus CSA $/SF (blended) | B29: =B25 -> 344.66489
A30: CSA % of total construction | B30: =B21/'Campus Rollup'!H16 -> 0.25335047
A31: CSA % of all-in TDC | B31: =B21/'Total Development Cost'!C35 -> 0.18225705
A34: — chart source data —
A35: =A6 -> Earthwork (Div 31) | B35: =B6 -> 25614732
A36: =A7 -> Exterior Improvements (Div 32) | B36: =B7 -> 9371809.5
A37: =A8 -> Utilities (Div 33) | B37: =B8 -> 63598602
A38: =A9 -> Concrete (Div 03) | B38: =B9 -> 33466040
A39: =A10 -> Metals / Structural Steel (Div 05) | B39: =B10 -> 40836400
A40: =A11 -> Thermal & Moisture (Div 07) | B40: =B11 -> 38165651
A41: =A12 -> Openings (Div 08) | B41: =B12 -> 13742210
A42: =A13 -> Finishes (Div 09) | B42: =B13 -> 33189552
A43: =A14 -> Specialties (Div 10) | B43: =B14 -> 4010233.4
A44: =A15 -> Masonry (Div 04) | B44: =B15 -> 5656068
A45: =A16 -> Wood, Plastics & Composites (Div 06) | B45: =B16 -> 1233678.6
A46: =A17 -> Equipment (Div 11) | B46: =B17 -> 1525590
...

Sheet Unit Cost Database
A1: DATA CENTER — UNIT COST DATABASE / STANDARD REFERENCE PRICING | H1: Pricing Tier: | I1: ='Scenario & Presets'!B15 -> Low
A3: CSI Code | B3: Description | C3: Unit | D3: Low Range | E3: Mid Range | F3: High Range | G3: Notes | H3: Selected Price
A4: 31 10 00 | B4: Site Clearing & Demolition | C4: SF | D4: 1.5 | E4: 2.5 | F4: 4 | G4: Per SF of site area; varies with existing conditions | H4: =IF(OR($A4="",$A4="—"),"",CHOOSE(MATCH($I$1,{"Low","Mid","High"},0),D4,E4,F4)) -> 1.5
A5: 31 22 00 | B5: Grading & Excavation | C5: CY | D5: 8 | E5: 15 | F5: 25 | G5: Per cubic yard; rock excavation at high end | H5: =IF(OR($A5="",$A5="—"),"",CHOOSE(MATCH($I$1,{"Low","Mid","High"},0),D5,E5,F5)) -> 8
A6: 31 23 00 | B6: Fill, Backfill & Compaction | C6: CY | D6: 12 | E6: 22 | F6: 35 | G6: Includes import fill, placement, and proof-roll | H6: =IF(OR($A6="",$A6="—"),"",CHOOSE(MATCH($I$1,{"Low","Mid","High"},0),D6,E6,F6)) -> 12
A7: 31 62 00 | B7: Driven Piles | C7: LF | D7: 35 | E7: 55 | F7: 85 | G7: Per LF of pile; steel H-pile typical | H7: =IF(OR($A7="",$A7="—"),"",CHOOSE(MATCH($I$1,{"Low","Mid","High"},0),D7,E7,F7)) -> 35
A8: 32 12 00 | B8: Asphalt Paving | C8: SF | D8: 3.5 | E8: 5.5 | F8: 8 | G8: 4" HMA over 8" aggregate base | H8: =IF(OR($A8="",$A8="—"),"",CHOOSE(MATCH($I$1,{"Low","Mid","High"},0),D8,E8,F8)) -> 3.5
A9: 32 13 00 | B9: Concrete Paving | C9: SF | D9: 7 | E9: 11 | F9: 16 | G9: 6" reinforced concrete; truck aprons higher | H9: =IF(OR($A9="",$A9="—"),"",CHOOSE(MATCH($I$1,{"Low","Mid","High"},0),D9,E9,F9)) -> 7
A10: 32 31 00 | B10: Security Fencing — 8' Chain Link + Barbed Wire | C10: LF | D10: 45 | E10: 75 | F10: 120 | G10: Per LF including gates; K-rated bollards separate | H10: =IF(OR($A10="",$A10="—"),"",CHOOSE(MATCH($I$1,{"Low","Mid","High"},0),D10,E10,F10)) -> 45
A11: 33 10 00 | B11: Water Distribution — Main Connection | C11: LS | D11: 75000 | E11: 150000 | F11: 300000 | G11: Tap, meter, backflow, site distribution | H11: =IF(OR($A11="",$A11="—"),"",CHOOSE(MATCH($I$1,{"Low","Mid","High"},0),D11,E11,F11)) -> 75000
A12: 33 40 00 | B12: Storm Drainage System | C12: SF | D12: 2.5 | E12: 5 | F12: 9 | G12: Per SF of site; includes detention/retention | H12: =IF(OR($A12="",$A12="—"),"",CHOOSE(MATCH($I$1,{"Low","Mid","High"},0),D12,E12,F12)) -> 2.5
A13: 33 50 00 | B13: Fuel Oil Distribution — Generator Farm | C13: GAL | D13: 3 | E13: 5.5 | F13: 8.5 | G13: Per gallon of storage capacity; AST w/ piping | H13: =IF(OR($A13="",$A13="—"),"",CHOOSE(MATCH($I$1,{"Low","Mid","High"},0),D13,E13,F13)) -> 3
A14: 33 71 00 | B14: Electrical Utility — Primary Service Entrance | C14: MW | D14: 250000 | E14: 450000 | F14: 750000 | G14: Per MW; includes ductbank, switchgear pad, metering | H14: =IF(OR($A14="",$A14="—"),"",CHOOSE(MATCH($I$1,{"Low","Mid","High"},0),D14,E14,F14)) -> 250000
A15: 03 30 00 | B15: Cast-in-Place Concrete — Foundations | C15: CY | D15: 450 | E15: 650 | F15: 950 | G15: Per CY placed; includes form, rebar, finish | H15: =IF(OR($A15="",$A15="—"),"",CHOOSE(MATCH($I$1,{"Low","Mid","High"},0),D15,E15,F15)) -> 450
... A304: 25 95 00 | B304: Integration Testing, Tuning & Cx Support | C304: LS | D304: 800000 | E304: 1150000 | F304: 1600000 | G304: Integrated systems testing support to Cx | H304: =IF(OR($A304="",$A304="—"),"",CHOOSE(MATCH($I$1,{"Low","Mid","High"},0),D304,E304,F304)) -> 800000
A305: 31 23 20 | B305: Dewatering — Construction | C305: LS | D305: 350000 | E305: 550000 | F305: 850000 | G305: Added detail — earthwork supplemental | H305: =IF($A305="","",CHOOSE(MATCH($I$1,{"Low","Mid","High"},0),D305,E305,F305)) -> 350000
A306: 31 05 13 | B306: Aggregate Base Course — Under Slab/Paving | C306: CY | D306: 38 | E306: 52 | F306: 72 | G306: Added detail — earthwork supplemental | H306: =IF($A306="","",CHOOSE(MATCH($I$1,{"Low","Mid","High"},0),D306,E306,F306)) -> 38
A307: 31 32 00 | B307: Geotextile / Soil Stabilization Fabric | C307: SF | D307: 0.6 | E307: 0.95 | F307: 1.5 | G307: Added detail — earthwork supplemental | H307: =IF($A307="","",CHOOSE(MATCH($I$1,{"Low","Mid","High"},0),D307,E307,F307)) -> 0.6
A308: 32 32 50 | B308: Retaining Walls — Site | C308: SF | D308: 45 | E308: 68 | F308: 98 | G308: Added detail — exterior supplemental | H308: =IF($A308="","",CHOOSE(MATCH($I$1,{"Low","Mid","High"},0),D308,E308,F308)) -> 45
A309: 32 17 50 | B309: Guard Rails & Crash Barriers — Site | C309: LF | D309: 55 | E309: 85 | F309: 130 | G309: Added detail — exterior supplemental | H309: =IF($A309="","",CHOOSE(MATCH($I$1,{"Low","Mid","High"},0),D309,E309,F309)) -> 55
A310: 33 52 50 | B310: Natural Gas Service & Distribution | C310: LF | D310: 85 | E310: 130 | F310: 195 | G310: Added detail — utilities supplemental | H310: =IF($A310="","",CHOOSE(MATCH($I$1,{"Low","Mid","High"},0),D310,E310,F310)) -> 85
A311: 33 82 50 | B311: Communications Ductbank — Site | C311: LF | D311: 140 | E311: 200 | F311: 300 | G311: Added detail — utilities supplemental | H311: =IF($A311="","",CHOOSE(MATCH($I$1,{"Low","Mid","High"},0),D311,E311,F311)) -> 140
A312: 03 15 00 | B312: Under-Slab Vapor Barrier & Joints | C312: SF | D312: 1.1 | E312: 1.7 | F312: 2.6 | G312: Added detail — concrete supplemental | H312: =IF($A312="","",CHOOSE(MATCH($I$1,{"Low","Mid","High"},0),D312,E312,F312)) -> 1.1
A313: 03 30 70 | B313: Concrete Testing & Inspection | C313: LS | D313: 180000 | E313: 280000 | F313: 420000 | G313: Added detail — concrete supplemental | H313: =IF($A313="","",CHOOSE(MATCH($I$1,{"Low","Mid","High"},0),D313,E313,F313)) -> 180000
A314: 05 12 50 | B314: Anchor Bolts & Embed Plates — Structural | C314: LS | D314: 220000 | E314: 340000 | F314: 520000 | G314: Added detail — metals supplemental | H314: =IF($A314="","",CHOOSE(MATCH($I$1,{"Low","Mid","High"},0),D314,E314,F314)) -> 220000
A315: 07 27 00 | B315: Air & Vapor Barrier — Building Envelope | C315: SF | D315: 2.2 | E315: 3.4 | F315: 5 | G315: Added detail — thermal/moisture supplemental | H315: =IF($A315="","",CHOOSE(MATCH($I$1,{"Low","Mid","High"},0),D315,E315,F315)) -> 2.2
A316: 07 95 00 | B316: Expansion Joint Cover Assemblies | C316: LF | D316: 65 | E316: 95 | F316: 145 | G316: Added detail — thermal/moisture supplemental | H316: =IF($A316="","",CHOOSE(MATCH($I$1,{"Low","Mid","High"},0),D316,E316,F316)) -> 65
... A703: 33 40 03 | B703: Storm Drainage — Install | C703: LS | D703: 300000 | E703: 600000 | F703: 1080000 | G703: Decomposed from 33 40 00 | H703: =IF($A703="","",CHOOSE(MATCH($I$1,{"Low","Mid","High"},0),D703,E703,F703)) -> 300000
A704: CX 02 00 | B704: Level 1 Cx — Factory Witness Testing | C704: MW | D704: 35000 | E704: 40250 | F704: 47250 | G704: Added from Construction Budget CX/SC section; Low = current budget basis (NoVA). | H704: =IF(OR($A704="",$A704="—"),"",CHOOSE(MATCH($I$1,{"Low","Mid","High"},0),D704,E704,F704)) -> 35000
A705: CX 03 00 | B705: Level 2 Cx — Component Verification (Individual Equipment) | C705: MW | D705: 45000 | E705: 51750 | F705: 60750 | G705: Added from Construction Budget CX/SC section; Low = current budget basis (NoVA). | H705: =IF(OR($A705="",$A705="—"),"",CHOOSE(MATCH($I$1,{"Low","Mid","High"},0),D705,E705,F705)) -> 45000
A706: CX 04 00 | B706: Level 3 Cx — Subsystem Verification | C706: MW | D706: 55000 | E706: 63250 | F706: 74250 | G706: Added from Construction Budget CX/SC section; Low = current budget basis (NoVA). | H706: =IF(OR($A706="",$A706="—"),"",CHOOSE(MATCH($I$1,{"Low","Mid","High"},0),D706,E706,F706)) -> 55000
A707: CX 05 00 | B707: Level 4 Cx — System Verification (Integrated) | C707: MW | D707: 75000 | E707: 86250 | F707: 101250 | G707: Added from Construction Budget CX/SC section; Low = current budget basis (NoVA). | H707: =IF(OR($A707="",$A707="—"),"",CHOOSE(MATCH($I$1,{"Low","Mid","High"},0),D707,E707,F707)) -> 75000
A708: CX 07 00 | B708: Performance Verification Testing | C708: MW | D708: 65000 | E708: 74750 | F708: 87750 | G708: Added from Construction Budget CX/SC section; Low = current budget basis (NoVA). | H708: =IF(OR($A708="",$A708="—"),"",CHOOSE(MATCH($I$1,{"Low","Mid","High"},0),D708,E708,F708)) -> 65000
A709: CX 08 00 | B709: Seasonal Testing — Summer / Winter Peaks | C709: MW | D709: 45000 | E709: 51750 | F709: 60750 | G709: Added from Construction Budget CX/SC section; Low = current budget basis (NoVA). | H709: =IF(OR($A709="",$A709="—"),"",CHOOSE(MATCH($I$1,{"Low","Mid","High"},0),D709,E709,F709)) -> 45000
A710: CX 09 00 | B710: Failure Mode & Effects Testing (FMEA) | C710: MW | D710: 35000 | E710: 40250 | F710: 47250 | G710: Added from Construction Budget CX/SC section; Low = current budget basis (NoVA). | H710: =IF(OR($A710="",$A710="—"),"",CHOOSE(MATCH($I$1,{"Low","Mid","High"},0),D710,E710,F710)) -> 35000
A711: CX 10 00 | B711: Documentation — O&M Manuals, As-Builts | C711: MW | D711: 25000 | E711: 28750 | F711: 33750 | G711: Added from Construction Budget CX/SC section; Low = current budget basis (NoVA). | H711: =IF(OR($A711="",$A711="—"),"",CHOOSE(MATCH($I$1,{"Low","Mid","High"},0),D711,E711,F711)) -> 25000
A712: CX 11 00 | B712: Staff Training — Critical Systems Operation | C712: MW | D712: 18000 | E712: 20700 | F712: 24300 | G712: Added from Construction Budget CX/SC section; Low = current budget basis (NoVA). | H712: =IF(OR($A712="",$A712="—"),"",CHOOSE(MATCH($I$1,{"Low","Mid","High"},0),D712,E712,F712)) -> 18000
A713: CX 12 00 | B713: Uptime Institute Tier Certification Support | C713: LS | D713: 250000 | E713: 287500 | F713: 337500 | G713: Added from Construction Budget CX/SC section; Low = current budget basis (NoVA). | H713: =IF(OR($A713="",$A713="—"),"",CHOOSE(MATCH($I$1,{"Low","Mid","High"},0),D713,E713,F713)) -> 250000
A714: CX 13 00 | B714: Temporary Provisions — Load Banks for IST | C714: MW | D714: 35000 | E714: 40250 | F714: 47250 | G714: Added from Construction Budget CX/SC section; Low = current budget basis (NoVA). | H714: =IF(OR($A714="",$A714="—"),"",CHOOSE(MATCH($I$1,{"Low","Mid","High"},0),D714,E714,F714)) -> 35000
A715: CX 14 00 | B715: Deficiency Tracking & Remediation | C715: MW | D715: 25000 | E715: 28750 | F715: 33750 | G715: Added from Construction Budget CX/SC section; Low = current budget basis (NoVA). | H715: =IF(OR($A715="",$A715="—"),"",CHOOSE(MATCH($I$1,{"Low","Mid","High"},0),D715,E715,F715)) -> 25000
...

Sheet Allowances & Alternates
A1: DATA CENTER — ALLOWANCES & ALTERNATES
A3: ALLOWANCES
A4: # | B4: Description | C4: CSI Div | D4: Allowance Amt | E4: Actual Cost | F4: Variance | G4: Status | H4: Vendor | I4: Notes
A5: 1 | B5: Owner-Furnished Equipment Allowance | C5: 27 | D5: 2500000 | E5: 0 | F5: =D5-E5 -> 2500000 | G5: Pending
A6: 2 | B6: Fiber Optic Entrance — Carrier Buildout | C6: 27 | D6: 1200000 | E6: 0 | F6: =D6-E6 -> 1200000 | G6: Pending
A7: 3 | B7: Office / NOC Furniture | C7: 10 | D7: 850000 | E7: 0 | F7: =D7-E7 -> 850000 | G7: Pending
